Workbook

Sheet Cover
A1: THE $5 TRILLION MERGER NOBODY CAN PRICE: SPACEX + TESLA
A3: Live Financial Model — DCF, Sum-of-the-Parts, Merger / Accretion-Dilution, Synergy & Probability-Weighted Valuation
A4: Prerna Dudhmande | B.Tech (Computer Science) | Independent Equity & M&A Research Project
A5: Companion model to the full written report. All figures as of June 16, 2026 unless noted. Educational / portfolio project — not investment advice.
A7: How to use this workbook
A8: • Blue text = hardcoded input / assumption (change these to run your own scenarios)
A9: • Black text = formula calculated within the same sheet
A10: • Green text = formula linking to another sheet (e.g., pulling from Assumptions)
A11: • Tabs: Assumptions -> TSLA DCF -> SPCX DCF -> SOTP -> Merger Model -> Synergies -> Governance -> Prob-Weighted Val
A14: Headline outputs
A15: Metric | B15: Value | C15: Source tab
A16: Tesla (TSLA) current price | B16: =Assumptions!B6 -> 406.43 | C16: Assumptions
A17: Tesla 10-yr DCF implied price/share | B17: ='TSLA DCF'!B27 -> 48.964375 | C17: TSLA DCF
A18: Tesla DCF implied premium/(discount) | B18: ='TSLA DCF'!B29 -> -0.87952569 | C18: TSLA DCF
A19: SpaceX (SPCX) current price | B19: =Assumptions!C6 -> 200 | C19: Assumptions
A20: SpaceX 10-yr DCF implied price/share | B20: ='SPCX DCF'!B32 -> 10.41719 | C20: SPCX DCF
A21: SpaceX DCF implied premium/(discount) | B21: ='SPCX DCF'!B34 -> -0.94791405 | C21: SPCX DCF
A22: Combined market cap, no premium ($T) | B22: =(Assumptions!B8+Assumptions!C8)/1000 -> 4.1201768 | C22: Assumptions
A23: Breakeven exchange ratio (EBITDA/sh) | B23: ='Merger Model'!B19 -> 0.13075427 | C23: Merger Model
A24: Probability-weighted SPCX value | B24: ='Prob-Weighted Val'!D9 -> 197.76115 | C24: Prob-Weighted Val

Sheet Assumptions
A1: ASSUMPTIONS & MARKET DATA
A2: All figures as of June 16, 2026 unless noted. Blue = input; edit these cells to run scenarios.
A4: Market Data
B5: TSLA | C5: SPCX
A6: Price ($/share) | B6: 406.43 | C6: 200
A7: Shares Outstanding (B) | B7: 3.76 | C7: 12.96
A8: Market Cap ($B) | B8: =B6*B7 -> 1528.1768 | C8: =C6*C7 -> 2592
A9: Total Debt ($B) | B9: 15.89 | C9: 0
A10: Cash & Equivalents ($B) | B10: 44.74 | C10: 0
A11: Net Cash / (Debt) ($B) | B11: =B10-B9 -> 28.85 | C11: =C10-C9 -> 0
A12: Source: company 8-K/10-K filings, S-1 prospectus, and June 2026 trading data.
A14: CAPM / WACC Inputs
A15: Risk-Free Rate | B15: 0.043
A16: Equity Risk Premium | B16: 0.05
A17: TSLA Beta | B17: 1.8
A18: SPCX Beta | B18: 1.95
A19: TSLA Pre-Tax Cost of Debt | B19: 0.055
A20: TSLA WACC Tax Rate | B20: 0.18
A21: TSLA Cost of Equity | B21: =B15+B17*B16 -> 0.133
A22: TSLA After-Tax Cost of Debt | B22: =B19*(1-B20) -> 0.0451
A23: TSLA Weight of Equity | B23: =B8/(B8+B9) -> 0.98970899
A24: TSLA Weight of Debt | B24: =1-B23 -> 0.010291006
A25: TSLA WACC | B25: =B23*B21+B24*B22 -> 0.13209542
A26: SPCX Cost of Equity / WACC (no mat'l debt) | B26: =B15+B18*B16 -> 0.1405
A27: TSLA DCF NOPAT Tax Rate | B27: 0.16
A28: SPCX Statutory Tax Rate (post-NOL) | B28: 0.21
A29: SPCX Cumulative NOL Balance ($B) | B29: 41.3
A30: TSLA Terminal Growth Rate | B30: 0.035
A31: SPCX Terminal Growth Rate | B31: 0.04
A32: Incremental NWC % (of revenue growth $, both cos.) | B32: 0.04
A33: Source: risk-free rate = 10Y UST yield proxy; ERP = standard large-cap equity risk premium; betas = trailing third-party estimates.
A35: Tesla FY2025A Financials ($B unless noted)
A36: Revenue | B36: 94.83
A37: Gross Profit | B37: 17.09
A38: Gross Margin | B38: =B37/B36 -> 0.18021723
A39: Operating Income | B39: 4.36
A40: Operating Margin | B40: =B39/B36 -> 0.045977011
A41: Adjusted EBITDA | B41: 14.6
A42: Adjusted EBITDA Margin | B42: =B41/B36 -> 0.15395972
A43: GAAP Net Income | B43: 3.79
...

Sheet TSLA DCF
A1: TESLA (TSLA) — 10-YEAR DISCOUNTED CASH FLOW
A2: All $ in billions unless noted. Assumptions linked from the Assumptions tab (green).
A3: Fiscal Year | B3: =Assumptions!B60 -> 2026 | C3: =Assumptions!C60 -> 2027 | D3: =Assumptions!D60 -> 2028 | E3: =Assumptions!E60 -> 2029 | F3: =Assumptions!F60 -> 2030 | G3: =Assumptions!G60 -> 2031 | H3: =Assumptions!H60 -> 2032 | I3: =Assumptions!I60 -> 2033 | ... K3: =Assumptions!K60 -> 2035
A4: Revenue ($B) | B4: =Assumptions!$B$36*(1+Assumptions!B61) -> 103.3647 | C4: =B4*(1+Assumptions!C61) -> 115.25164 | D4: =C4*(1+Assumptions!D61) -> 131.38687 | E4: =D4*(1+Assumptions!E61) -> 151.0949 | F4: =E4*(1+Assumptions!F61) -> 173.75914 | G4: =F4*(1+Assumptions!G61) -> 196.34782 | H4: =G4*(1+Assumptions!H61) -> 217.94608 | I4: =H4*(1+Assumptions!I61) -> 238.65096 | J4: =I4*(1+Assumptions!J61) -> 257.74304 | K4: =J4*(1+Assumptions!K61) -> 275.78505
A5: Revenue Growth % | B5: =Assumptions!B61 -> 0.09 | C5: =Assumptions!C61 -> 0.115 | D5: =Assumptions!D61 -> 0.14 | E5: =Assumptions!E61 -> 0.15 | F5: =Assumptions!F61 -> 0.15 | G5: =Assumptions!G61 -> 0.13 | H5: =Assumptions!H61 -> 0.11 | I5: =Assumptions!I61 -> 0.095 | ... K5: =Assumptions!K61 -> 0.07
A6: EBITDA ($B) | B6: =B4*Assumptions!B62 -> 17.055176 | C6: =C4*Assumptions!C62 -> 20.514792 | D6: =D4*Assumptions!D62 -> 25.226279 | E6: =E4*Assumptions!E62 -> 30.974455 | F6: =F4*Assumptions!F62 -> 37.879492 | G6: =G4*Assumptions!G62 -> 44.767304 | H6: =H4*Assumptions!H62 -> 51.21733 | I6: =I4*Assumptions!I62 -> 57.276231 | ... K6: =K4*Assumptions!K62 -> 67.567338
A7: EBITDA Margin % | B7: =B6/B4 -> 0.165 | C7: =C6/C4 -> 0.178 | D7: =D6/D4 -> 0.192 | E7: =E6/E4 -> 0.205 | F7: =F6/F4 -> 0.218 | G7: =G6/G4 -> 0.228 | H7: =H6/H4 -> 0.235 | I7: =I6/I4 -> 0.24 | ... K7: =K6/K4 -> 0.245
A8: D&A ($B) | B8: =B4*Assumptions!B63 -> 6.201882 | C8: =C4*Assumptions!C63 -> 7.1456017 | D8: =D4*Assumptions!D63 -> 8.5401466 | E8: =E4*Assumptions!E63 -> 10.274453 | F8: =F4*Assumptions!F63 -> 12.16314 | G8: =G4*Assumptions!G63 -> 14.137043 | H8: =H4*Assumptions!H63 -> 16.12801 | I8: =I4*Assumptions!I63 -> 17.898822 | ... K8: =K4*Assumptions!K63 -> 21.235449
A9: EBIT ($B) | B9: =B6-B8 -> 10.853293 | C9: =C6-C8 -> 13.36919 | D9: =D6-D8 -> 16.686133 | E9: =E6-E8 -> 20.700001 | F9: =F6-F8 -> 25.716352 | G9: =G6-G8 -> 30.63026 | H9: =H6-H8 -> 35.08932 | I9: =I6-I8 -> 39.377409 | ... K9: =K6-K8 -> 46.331889
A10: NOPAT ($B) | B10: =B9*(1-Assumptions!$B$27) -> 9.1167665 | C10: =C9*(1-Assumptions!$B$27) -> 11.23012 | D10: =D9*(1-Assumptions!$B$27) -> 14.016351 | E10: =E9*(1-Assumptions!$B$27) -> 17.388001 | F10: =F9*(1-Assumptions!$B$27) -> 21.601736 | G10: =G9*(1-Assumptions!$B$27) -> 25.729419 | H10: =H9*(1-Assumptions!$B$27) -> 29.475028 | I10: =I9*(1-Assumptions!$B$27) -> 33.077023 | ... K10: =K9*(1-Assumptions!$B$27) -> 38.918786
A11: Capex ($B) | B11: =B4*Assumptions!B64 -> 23.773881 | C11: =C4*Assumptions!C64 -> 23.626586 | D11: =D4*Assumptions!D64 -> 24.306571 | E11: =E4*Assumptions!E64 -> 24.930659 | F11: =F4*Assumptions!F64 -> 25.195075 | G11: =G4*Assumptions!G64 -> 24.543478 | H11: =H4*Assumptions!H64 -> 23.974069 | I11: =I4*Assumptions!I64 -> 22.671841 | ... K11: =K4*Assumptions!K64 -> 21.511234
A12: Incremental NWC ($B) | B12: =B4*Assumptions!B61*Assumptions!$B$32 -> 0.37211292 | C12: =C4*Assumptions!C61*Assumptions!$B$32 -> 0.53015755 | D12: =D4*Assumptions!D61*Assumptions!$B$32 -> 0.73576647 | E12: =E4*Assumptions!E61*Assumptions!$B$32 -> 0.9065694 | F12: =F4*Assumptions!F61*Assumptions!$B$32 -> 1.0425548 | G12: =G4*Assumptions!G61*Assumptions!$B$32 -> 1.0210087 | H12: =H4*Assumptions!H61*Assumptions!$B$32 -> 0.95896277 | I12: =I4*Assumptions!I61*Assumptions!$B$32 -> 0.90687366 | ... K12: =K4*Assumptions!K61*Assumptions!$B$32 -> 0.77219814
A13: Unlevered Free Cash Flow ($B) | B13: =B10+B8-B11-B12 -> -8.8273454 | C13: =C10+C8-C11-C12 -> -5.7810223 | D13: =D10+D8-D11-D12 -> -2.4858396 | E13: =E10+E8-E11-E12 -> 1.8252264 | F13: =F10+F8-F11-F12 -> 7.5272458 | G13: =G10+G8-G11-G12 -> 14.301975 | H13: =H10+H8-H11-H12 -> 20.670007 | I13: =I10+I8-I11-I12 -> 27.39713 | ... K13: =K10+K8-K11-K12 -> 37.870803
A14: Discount Period | B14: 1 | C14: 2 | D14: 3 | E14: 4 | F14: 5 | G14: 6 | H14: 7 | I14: 8 | J14: 9 | K14: 10
A15: Discount Factor | B15: =1/(1+Assumptions!$B$25)^B14 -> 0.88331777 | C15: =1/(1+Assumptions!$B$25)^C14 -> 0.78025028 | D15: =1/(1+Assumptions!$B$25)^D14 -> 0.68920893 | E15: =1/(1+Assumptions!$B$25)^E14 -> 0.6087905 | F15: =1/(1+Assumptions!$B$25)^F14 -> 0.53775546 | G15: =1/(1+Assumptions!$B$25)^G14 -> 0.47500896 | H15: =1/(1+Assumptions!$B$25)^H14 -> 0.41958385 | I15: =1/(1+Assumptions!$B$25)^I14 -> 0.37062587 | ... K15: =1/(1+Assumptions!$B$25)^K14 -> 0.28918094
A16: PV of FCF ($B) | B16: =B13*B15 -> -7.797351 | C16: =C13*C15 -> -4.5106443 | D16: =D13*D15 -> -1.7132629 | E16: =E13*E15 -> 1.1111805 | F16: =F13*F15 -> 4.0478175 | G16: =G13*G15 -> 6.7935664 | H16: =H13*H15 -> 8.672801 | I16: =I13*I15 -> 10.154085 | ... K16: =K13*K15 -> 10.951514
A18: DCF Valuation Summary
A19: Sum PV of Explicit FCF ($B) | B19: =SUM(B16:K16) -> 38.5171
A20: Terminal Value, Undiscounted ($B) | B20: =K13*(1+Assumptions!$B$30)/(Assumptions!$B$25-Assumptions!$B$30) -> 403.68826
A21: PV of Terminal Value ($B) | B21: =B20*K15 -> 116.73895
A22: PV of TV as % of EV | B22: =B21/(B19+B21) -> 0.7519124
A23: Implied Enterprise Value ($B) | B23: =B19+B21 -> 155.25605
A24: (+) Net Cash ($B) | B24: =Assumptions!B11 -> 28.85
A25: Implied Equity Value ($B) | B25: =B23+B24 -> 184.10605
A26: Diluted Shares Outstanding (B) | B26: =Assumptions!B7 -> 3.76
A27: Implied Price per Share | B27: =B25/B26 -> 48.964375
A28: Current Price | B28: =Assumptions!B6 -> 406.43
A29: Implied Premium / (Discount) to Current | B29: =B27/B28-1 -> -0.87952569
A31: Sensitivity: Implied Price per Share (WACC × Terminal Growth)
A32: WACC \ Terminal g | C32: 0.025 | D32: 0.03 | E32: 0.035 | F32: 0.04
B33: 0.115 | C33: =(SUMPRODUCT($B$13:$K$13,(1+$B33)^-($B$14:$K$14))+($K$13*(1+C$32)/($B33-C$32))*(1+$B33)^-10+Assumptions!$B$11)/Assumptions!$B$7 -> 58.235627 | D33: =(SUMPRODUCT($B$13:$K$13,(1+$B33)^-($B$14:$K$14))+($K$13*(1+D$32)/($B33-D$32))*(1+$B33)^-10+Assumptions!$B$11)/Assumptions!$B$7 -> 60.707075 | E33: =(SUMPRODUCT($B$13:$K$13,(1+$B33)^-($B$14:$K$14))+($K$13*(1+E$32)/($B33-E$32))*(1+$B33)^-10+Assumptions!$B$11)/Assumptions!$B$7 -> 63.487454 | F33: =(SUMPRODUCT($B$13:$K$13,(1+$B33)^-($B$14:$K$14))+($K$13*(1+F$32)/($B33-F$32))*(1+$B33)^-10+Assumptions!$B$11)/Assumptions!$B$7 -> 66.638549
B34: 0.125 | C34: =(SUMPRODUCT($B$13:$K$13,(1+$B34)^-($B$14:$K$14))+($K$13*(1+C$32)/($B34-C$32))*(1+$B34)^-10+Assumptions!$B$11)/Assumptions!$B$7 -> 50.382452 | D34: =(SUMPRODUCT($B$13:$K$13,(1+$B34)^-($B$14:$K$14))+($K$13*(1+D$32)/($B34-D$32))*(1+$B34)^-10+Assumptions!$B$11)/Assumptions!$B$7 -> 52.21895 | E34: =(SUMPRODUCT($B$13:$K$13,(1+$B34)^-($B$14:$K$14))+($K$13*(1+E$32)/($B34-E$32))*(1+$B34)^-10+Assumptions!$B$11)/Assumptions!$B$7 -> 54.259503 | F34: =(SUMPRODUCT($B$13:$K$13,(1+$B34)^-($B$14:$K$14))+($K$13*(1+F$32)/($B34-F$32))*(1+$B34)^-10+Assumptions!$B$11)/Assumptions!$B$7 -> 56.540121
B35: 0.1321 | C35: =(SUMPRODUCT($B$13:$K$13,(1+$B35)^-($B$14:$K$14))+($K$13*(1+C$32)/($B35-C$32))*(1+$B35)^-10+Assumptions!$B$11)/Assumptions!$B$7 -> 45.790608 | D35: =(SUMPRODUCT($B$13:$K$13,(1+$B35)^-($B$14:$K$14))+($K$13*(1+D$32)/($B35-D$32))*(1+$B35)^-10+Assumptions!$B$11)/Assumptions!$B$7 -> 47.298285 | E35: =(SUMPRODUCT($B$13:$K$13,(1+$B35)^-($B$14:$K$14))+($K$13*(1+E$32)/($B35-E$32))*(1+$B35)^-10+Assumptions!$B$11)/Assumptions!$B$7 -> 48.961233 | F35: =(SUMPRODUCT($B$13:$K$13,(1+$B35)^-($B$14:$K$14))+($K$13*(1+F$32)/($B35-F$32))*(1+$B35)^-10+Assumptions!$B$11)/Assumptions!$B$7 -> 50.80474
B36: 0.14 | C36: =(SUMPRODUCT($B$13:$K$13,(1+$B36)^-($B$14:$K$14))+($K$13*(1+C$32)/($B36-C$32))*(1+$B36)^-10+Assumptions!$B$11)/Assumptions!$B$7 -> 41.427781 | D36: =(SUMPRODUCT($B$13:$K$13,(1+$B36)^-($B$14:$K$14))+($K$13*(1+D$32)/($B36-D$32))*(1+$B36)^-10+Assumptions!$B$11)/Assumptions!$B$7 -> 42.651981 | E36: =(SUMPRODUCT($B$13:$K$13,(1+$B36)^-($B$14:$K$14))+($K$13*(1+E$32)/($B36-E$32))*(1+$B36)^-10+Assumptions!$B$11)/Assumptions!$B$7 -> 43.992772 | F36: =(SUMPRODUCT($B$13:$K$13,(1+$B36)^-($B$14:$K$14))+($K$13*(1+F$32)/($B36-F$32))*(1+$B36)^-10+Assumptions!$B$11)/Assumptions!$B$7 -> 45.467642
B37: 0.15 | C37: =(SUMPRODUCT($B$13:$K$13,(1+$B37)^-($B$14:$K$14))+($K$13*(1+C$32)/($B37-C$32))*(1+$B37)^-10+Assumptions!$B$11)/Assumptions!$B$7 -> 36.800565 | D37: =(SUMPRODUCT($B$13:$K$13,(1+$B37)^-($B$14:$K$14))+($K$13*(1+D$32)/($B37-D$32))*(1+$B37)^-10+Assumptions!$B$11)/Assumptions!$B$7 -> 37.754931 | E37: =(SUMPRODUCT($B$13:$K$13,(1+$B37)^-($B$14:$K$14))+($K$13*(1+E$32)/($B37-E$32))*(1+$B37)^-10+Assumptions!$B$11)/Assumptions!$B$7 -> 38.792285 | F37: =(SUMPRODUCT($B$13:$K$13,(1+$B37)^-($B$14:$K$14))+($K$13*(1+F$32)/($B37-F$32))*(1+$B37)^-10+Assumptions!$B$11)/Assumptions!$B$7 -> 39.923944
A38: Base case (WACC 13.21%, g 3.5%) highlighted via the B19:B29 waterfall above.

Sheet SPCX DCF
A1: SPACEX (SPCX) — 10-YEAR DISCOUNTED CASH FLOW
A2: All $ in billions unless noted. NOL = net operating loss carryforward shield. Assumptions linked (green).
A3: Fiscal Year | B3: =Assumptions!B68 -> 2026 | C3: =Assumptions!C68 -> 2027 | D3: =Assumptions!D68 -> 2028 | E3: =Assumptions!E68 -> 2029 | F3: =Assumptions!F68 -> 2030 | G3: =Assumptions!G68 -> 2031 | H3: =Assumptions!H68 -> 2032 | I3: =Assumptions!I68 -> 2033 | ... K3: =Assumptions!K68 -> 2035
A4: Revenue ($B) | B4: =Assumptions!$B$53*(1+Assumptions!B69) -> 25.7646 | C4: =B4*(1+Assumptions!C69) -> 34.524564 | D4: =C4*(1+Assumptions!D69) -> 44.881933 | E4: =D4*(1+Assumptions!E69) -> 57.000055 | F4: =E4*(1+Assumptions!F69) -> 70.680068 | G4: =F4*(1+Assumptions!G69) -> 85.522883 | H4: =G4*(1+Assumptions!H69) -> 101.77223 | I4: =H4*(1+Assumptions!I69) -> 119.07351 | J4: =I4*(1+Assumptions!J69) -> 136.93454 | K4: =J4*(1+Assumptions!K69) -> 156.10537
A5: Revenue Growth % | B5: =Assumptions!B69 -> 0.38 | C5: =Assumptions!C69 -> 0.34 | D5: =Assumptions!D69 -> 0.3 | E5: =Assumptions!E69 -> 0.27 | F5: =Assumptions!F69 -> 0.24 | G5: =Assumptions!G69 -> 0.21 | H5: =Assumptions!H69 -> 0.19 | I5: =Assumptions!I69 -> 0.17 | ... K5: =Assumptions!K69 -> 0.14
A6: EBITDA ($B) | B6: =B4*Assumptions!B70 -> 9.146433 | C6: =C4*Assumptions!C70 -> 12.601466 | D6: =D4*Assumptions!D70 -> 16.830725 | E6: =E4*Assumptions!E70 -> 21.945021 | F6: =F4*Assumptions!F70 -> 27.918627 | G6: =G4*Assumptions!G70 -> 34.636768 | H6: =H4*Assumptions!H70 -> 42.235476 | I6: =I4*Assumptions!I70 -> 50.606242 | ... K6: =K4*Assumptions!K70 -> 69.46689
A7: EBITDA Margin % | B7: =B6/B4 -> 0.355 | C7: =C6/C4 -> 0.365 | D7: =D6/D4 -> 0.375 | E7: =E6/E4 -> 0.385 | F7: =F6/F4 -> 0.395 | G7: =G6/G4 -> 0.405 | H7: =H6/H4 -> 0.415 | I7: =I6/I4 -> 0.425 | ... K7: =K6/K4 -> 0.445
A8: D&A ($B) | B8: =B4*Assumptions!B71 -> 2.189991 | C8: =C4*Assumptions!C71 -> 3.1072108 | D8: =D4*Assumptions!D71 -> 4.2637837 | E8: =E4*Assumptions!E71 -> 5.7000055 | F8: =F4*Assumptions!F71 -> 7.4214072 | G8: =G4*Assumptions!G71 -> 9.4075171 | H8: =H4*Assumptions!H71 -> 11.703807 | I8: =I4*Assumptions!I71 -> 14.288821 | ... K8: =K4*Assumptions!K71 -> 19.357066
A9: EBIT ($B) | B9: =B6-B8 -> 6.956442 | C9: =C6-C8 -> 9.4942551 | D9: =D6-D8 -> 12.566941 | E9: =E6-E8 -> 16.245016 | F9: =F6-F8 -> 20.49722 | G9: =G6-G8 -> 25.22925 | H9: =H6-H8 -> 30.531669 | I9: =I6-I8 -> 36.31742 | ... K9: =K6-K8 -> 50.109824
A10: NOL Balance, Beginning ($B) | B10: =Assumptions!$B$29 -> 41.3 | C10: =B14 -> 34.343558 | D10: =C14 -> 24.849303 | E10: =D14 -> 12.282362 | F10: =E14 -> 0 | G10: =F14 -> 0 | H10: =G14 -> 0 | I10: =H14 -> 0 | J10: =I14 -> 0 | K10: =J14 -> 0
A11: NOL Utilized ($B) | B11: =MIN(B10,MAX(B9,0)) -> 6.956442 | C11: =MIN(C10,MAX(C9,0)) -> 9.4942551 | D11: =MIN(D10,MAX(D9,0)) -> 12.566941 | E11: =MIN(E10,MAX(E9,0)) -> 12.282362 | F11: =MIN(F10,MAX(F9,0)) -> 0 | G11: =MIN(G10,MAX(G9,0)) -> 0 | H11: =MIN(H10,MAX(H9,0)) -> 0 | I11: =MIN(I10,MAX(I9,0)) -> 0 | ... K11: =MIN(K10,MAX(K9,0)) -> 0
A12: Taxable Income ($B) | B12: =MAX(B9,0)-B11 -> 0 | C12: =MAX(C9,0)-C11 -> 0 | D12: =MAX(D9,0)-D11 -> 0 | E12: =MAX(E9,0)-E11 -> 3.9626541 | F12: =MAX(F9,0)-F11 -> 20.49722 | G12: =MAX(G9,0)-G11 -> 25.22925 | H12: =MAX(H9,0)-H11 -> 30.531669 | I12: =MAX(I9,0)-I11 -> 36.31742 | ... K12: =MAX(K9,0)-K11 -> 50.109824
A13: Cash Tax ($B) | B13: =B12*Assumptions!$B$28 -> 0 | C13: =C12*Assumptions!$B$28 -> 0 | D13: =D12*Assumptions!$B$28 -> 0 | E13: =E12*Assumptions!$B$28 -> 0.83215736 | F13: =F12*Assumptions!$B$28 -> 4.3044162 | G13: =G12*Assumptions!$B$28 -> 5.2981426 | H13: =H12*Assumptions!$B$28 -> 6.4116505 | I13: =I12*Assumptions!$B$28 -> 7.6266583 | ... K13: =K12*Assumptions!$B$28 -> 10.523063
A14: NOL Balance, Ending ($B) | B14: =B10-B11 -> 34.343558 | C14: =C10-C11 -> 24.849303 | D14: =D10-D11 -> 12.282362 | E14: =E10-E11 -> 0 | F14: =F10-F11 -> 0 | G14: =G10-G11 -> 0 | H14: =H10-H11 -> 0 | I14: =I10-I11 -> 0 | ... K14: =K10-K11 -> 0
A15: NOPAT ($B) | B15: =B9-B13 -> 6.956442 | C15: =C9-C13 -> 9.4942551 | D15: =D9-D13 -> 12.566941 | E15: =E9-E13 -> 15.412858 | F15: =F9-F13 -> 16.192804 | G15: =G9-G13 -> 19.931108 | H15: =H9-H13 -> 24.120019 | I15: =I9-I13 -> 28.690762 | ... K15: =K9-K13 -> 39.586761
A16: Capex ($B) | B16: =B4*Assumptions!B72 -> 8.244672 | C16: =C4*Assumptions!C72 -> 10.357369 | D16: =D4*Assumptions!D72 -> 12.566941 | E16: =E4*Assumptions!E72 -> 14.820014 | F16: =F4*Assumptions!F72 -> 16.963216 | G16: =G4*Assumptions!G72 -> 18.815034 | H16: =H4*Assumptions!H72 -> 20.863307 | I16: =I4*Assumptions!I72 -> 22.623967 | ... K16: =K4*Assumptions!K72 -> 25.757386
A17: Incremental NWC ($B) | B17: =(B4-Assumptions!$B$53)*Assumptions!$B$32 -> 0.283784 | C17: =(C4-B4)*Assumptions!$B$32 -> 0.35039856 | D17: =(D4-C4)*Assumptions!$B$32 -> 0.41429477 | E17: =(E4-D4)*Assumptions!$B$32 -> 0.48472488 | F17: =(F4-E4)*Assumptions!$B$32 -> 0.54720053 | G17: =(G4-F4)*Assumptions!$B$32 -> 0.59371257 | H17: =(H4-G4)*Assumptions!$B$32 -> 0.64997391 | I17: =(I4-H4)*Assumptions!$B$32 -> 0.69205117 | J17: =(J4-I4)*Assumptions!$B$32 -> 0.71444106 | K17: =(K4-J4)*Assumptions!$B$32 -> 0.7668334
A18: Unlevered Free Cash Flow ($B) | B18: =B15+B8-B16-B17 -> 0.617977 | C18: =C15+C8-C16-C17 -> 1.8936981 | D18: =D15+D8-D16-D17 -> 3.8494889 | E18: =E15+E8-E16-E17 -> 5.8081247 | F18: =F15+F8-F16-F17 -> 6.1037939 | G18: =G15+G8-G16-G17 -> 9.9298782 | H18: =H15+H8-H16-H17 -> 14.310544 | I18: =I15+I8-I16-I17 -> 19.663565 | ... K18: =K15+K8-K16-K17 -> 32.419607
A19: Discount Period | B19: 1 | C19: 2 | D19: 3 | E19: 4 | F19: 5 | G19: 6 | H19: 7 | I19: 8 | J19: 9 | K19: 10
A20: Discount Factor | B20: =1/(1+Assumptions!$B$26)^B19 -> 0.87680842 | C20: =1/(1+Assumptions!$B$26)^C19 -> 0.768793 | D20: =1/(1+Assumptions!$B$26)^D19 -> 0.67408417 | E20: =1/(1+Assumptions!$B$26)^E19 -> 0.59104268 | F20: =1/(1+Assumptions!$B$26)^F19 -> 0.5182312 | G20: =1/(1+Assumptions!$B$26)^G19 -> 0.45438947 | H20: =1/(1+Assumptions!$B$26)^H19 -> 0.39841252 | I20: =1/(1+Assumptions!$B$26)^I19 -> 0.34933145 | ... K20: =1/(1+Assumptions!$B$26)^K19 -> 0.26856357
A21: PV of FCF ($B) | B21: =B18*B20 -> 0.54184744 | C21: =C18*C20 -> 1.4558618 | D21: =D18*D20 -> 2.5948795 | E21: =E18*E20 -> 3.4328495 | F21: =F18*F20 -> 3.1631764 | G21: =G18*G20 -> 4.5120321 | H21: =H18*H20 -> 5.7014998 | I21: =I18*I20 -> 6.8691017 | ... K21: =K18*K20 -> 8.7067256
A23: DCF Valuation Summary
A24: Sum PV of Explicit FCF ($B) | B24: =SUM(B21:K21) -> 44.907333
A25: Terminal Value, Undiscounted ($B) | B25: =K18*(1+Assumptions!$B$31)/(Assumptions!$B$26-Assumptions!$B$31) -> 335.48649
A26: PV of Terminal Value ($B) | B26: =B25*K20 -> 90.099449
A27: PV of TV as % of EV | B27: =B26/(B24+B26) -> 0.6673698
A28: Implied Enterprise Value ($B) | B28: =B24+B26 -> 135.00678
A29: (+) Net Cash ($B) | B29: =Assumptions!C11 -> 0
A30: Implied Equity Value ($B) | B30: =B28+B29 -> 135.00678
A31: Total Shares Outstanding (B) | B31: =Assumptions!C7 -> 12.96
A32: Implied Price per Share | B32: =B30/B31 -> 10.41719
A33: Current Price | B33: =Assumptions!C6 -> 200
A34: Implied Premium / (Discount) to Current | B34: =B32/B33-1 -> -0.94791405
A36: Sensitivity: Implied Price per Share (WACC × Terminal Growth)
A37: WACC \ Terminal g | C37: 0.03 | D37: 0.035 | E37: 0.04 | F37: 0.045 | G37: 0.05
B38: 0.0975 | C38: =(SUMPRODUCT($B$18:$K$18,(1+$B38)^-($B$19:$K$19))+($K$18*(1+C$37)/($B38-C$37))*(1+$B38)^-10+Assumptions!$C$11)/Assumptions!$C$7 -> 19.635767 | D38: =(SUMPRODUCT($B$18:$K$18,(1+$B38)^-($B$19:$K$19))+($K$18*(1+D$37)/($B38-D$37))*(1+$B38)^-10+Assumptions!$C$11)/Assumptions!$C$7 -> 20.919126 | E38: =(SUMPRODUCT($B$18:$K$18,(1+$B38)^-($B$19:$K$19))+($K$18*(1+E$37)/($B38-E$37))*(1+$B38)^-10+Assumptions!$C$11)/Assumptions!$C$7 -> 22.425678 | F38: =(SUMPRODUCT($B$18:$K$18,(1+$B38)^-($B$19:$K$19))+($K$18*(1+F$37)/($B38-F$37))*(1+$B38)^-10+Assumptions!$C$11)/Assumptions!$C$7 -> 24.219193 | G38: =(SUMPRODUCT($B$18:$K$18,(1+$B38)^-($B$19:$K$19))+($K$18*(1+G$37)/($B38-G$37))*(1+$B38)^-10+Assumptions!$C$11)/Assumptions!$C$7 -> 26.390289
B39: 0.108 | C39: =(SUMPRODUCT($B$18:$K$18,(1+$B39)^-($B$19:$K$19))+($K$18*(1+C$37)/($B39-C$37))*(1+$B39)^-10+Assumptions!$C$11)/Assumptions!$C$7 -> 16.116479 | D39: =(SUMPRODUCT($B$18:$K$18,(1+$B39)^-($B$19:$K$19))+($K$18*(1+D$37)/($B39-D$37))*(1+$B39)^-10+Assumptions!$C$11)/Assumptions!$C$7 -> 16.989244 | E39: =(SUMPRODUCT($B$18:$K$18,(1+$B39)^-($B$19:$K$19))+($K$18*(1+E$37)/($B39-E$37))*(1+$B39)^-10+Assumptions!$C$11)/Assumptions!$C$7 -> 17.990357 | F39: =(SUMPRODUCT($B$18:$K$18,(1+$B39)^-($B$19:$K$19))+($K$18*(1+F$37)/($B39-F$37))*(1+$B39)^-10+Assumptions!$C$11)/Assumptions!$C$7 -> 19.150377 | G39: =(SUMPRODUCT($B$18:$K$18,(1+$B39)^-($B$19:$K$19))+($K$18*(1+G$37)/($B39-G$37))*(1+$B39)^-10+Assumptions!$C$11)/Assumptions!$C$7 -> 20.510401
B40: 0.1188 | C40: =(SUMPRODUCT($B$18:$K$18,(1+$B40)^-($B$19:$K$19))+($K$18*(1+C$37)/($B40-C$37))*(1+$B40)^-10+Assumptions!$C$11)/Assumptions!$C$7 -> 13.422417 | D40: =(SUMPRODUCT($B$18:$K$18,(1+$B40)^-($B$19:$K$19))+($K$18*(1+D$37)/($B40-D$37))*(1+$B40)^-10+Assumptions!$C$11)/Assumptions!$C$7 -> 14.034406 | E40: =(SUMPRODUCT($B$18:$K$18,(1+$B40)^-($B$19:$K$19))+($K$18*(1+E$37)/($B40-E$37))*(1+$B40)^-10+Assumptions!$C$11)/Assumptions!$C$7 -> 14.724059 | F40: =(SUMPRODUCT($B$18:$K$18,(1+$B40)^-($B$19:$K$19))+($K$18*(1+F$37)/($B40-F$37))*(1+$B40)^-10+Assumptions!$C$11)/Assumptions!$C$7 -> 15.50716 | G40: =(SUMPRODUCT($B$18:$K$18,(1+$B40)^-($B$19:$K$19))+($K$18*(1+G$37)/($B40-G$37))*(1+$B40)^-10+Assumptions!$C$11)/Assumptions!$C$7 -> 16.404085
B41: 0.13 | C41: =(SUMPRODUCT($B$18:$K$18,(1+$B41)^-($B$19:$K$19))+($K$18*(1+C$37)/($B41-C$37))*(1+$B41)^-10+Assumptions!$C$11)/Assumptions!$C$7 -> 11.293176 | D41: =(SUMPRODUCT($B$18:$K$18,(1+$B41)^-($B$19:$K$19))+($K$18*(1+D$37)/($B41-D$37))*(1+$B41)^-10+Assumptions!$C$11)/Assumptions!$C$7 -> 11.731447 | E41: =(SUMPRODUCT($B$18:$K$18,(1+$B41)^-($B$19:$K$19))+($K$18*(1+E$37)/($B41-E$37))*(1+$B41)^-10+Assumptions!$C$11)/Assumptions!$C$7 -> 12.218416 | F41: =(SUMPRODUCT($B$18:$K$18,(1+$B41)^-($B$19:$K$19))+($K$18*(1+F$37)/($B41-F$37))*(1+$B41)^-10+Assumptions!$C$11)/Assumptions!$C$7 -> 12.762674 | G41: =(SUMPRODUCT($B$18:$K$18,(1+$B41)^-($B$19:$K$19))+($K$18*(1+G$37)/($B41-G$37))*(1+$B41)^-10+Assumptions!$C$11)/Assumptions!$C$7 -> 13.374965
B42: 0.14 | C42: =(SUMPRODUCT($B$18:$K$18,(1+$B42)^-($B$19:$K$19))+($K$18*(1+C$37)/($B42-C$37))*(1+$B42)^-10+Assumptions!$C$11)/Assumptions!$C$7 -> 9.7942358 | D42: =(SUMPRODUCT($B$18:$K$18,(1+$B42)^-($B$19:$K$19))+($K$18*(1+D$37)/($B42-D$37))*(1+$B42)^-10+Assumptions!$C$11)/Assumptions!$C$7 -> 10.127238 | E42: =(SUMPRODUCT($B$18:$K$18,(1+$B42)^-($B$19:$K$19))+($K$18*(1+E$37)/($B42-E$37))*(1+$B42)^-10+Assumptions!$C$11)/Assumptions!$C$7 -> 10.49354 | F42: =(SUMPRODUCT($B$18:$K$18,(1+$B42)^-($B$19:$K$19))+($K$18*(1+F$37)/($B42-F$37))*(1+$B42)^-10+Assumptions!$C$11)/Assumptions!$C$7 -> 10.898401 | G42: =(SUMPRODUCT($B$18:$K$18,(1+$B42)^-($B$19:$K$19))+($K$18*(1+G$37)/($B42-G$37))*(1+$B42)^-10+Assumptions!$C$11)/Assumptions!$C$7 -> 11.348246
...

Sheet SOTP
A1: SUM-OF-THE-PARTS VALUATION
A3: Tesla — Core vs. Option Value
A4: Adjusted EBITDA, FY2025A ($B) | B4: =Assumptions!B41 -> 14.6
A5: Actual Enterprise Value ($B) | B5: =Assumptions!B8+Assumptions!B9-Assumptions!B10 -> 1499.3268
A7: Core Multiple | B7: Core EV ($B) | C7: Implied Option Value ($B) | D7: Option Value % of EV
A8: Low (9.0x) | B8: =Assumptions!B88*$B$4 -> 131.4 | C8: =$B$5-B8 -> 1367.9268 | D8: =C8/$B$5 -> 0.91236067
A9: Mid (11.0x) | B9: =Assumptions!B89*$B$4 -> 160.6 | C9: =$B$5-B9 -> 1338.7268 | D9: =C9/$B$5 -> 0.89288526
A10: High (13.0x) | B10: =Assumptions!B90*$B$4 -> 189.8 | C10: =$B$5-B10 -> 1309.5268 | D10: =C10/$B$5 -> 0.87340985
A12: Core multiple = normal industrial/auto multiple. Option value = residual EV attributable to FSD/Robotaxi/Optimus optionality.
A14: SpaceX — Segment Sum-of-the-Parts
A15: Starlink Adj. EBITDA ($B) | B15: =Assumptions!B49*Assumptions!B76 -> 7.182
A16: Launch/Space Adj. EBITDA ($B) | B16: =Assumptions!B52*Assumptions!B77 -> 1.148
A17: AI Segment Run-Rate Revenue ($B) | B17: =Assumptions!B85 -> 1
A19: Segment | B19: EV — Low ($B) | C19: EV — High ($B) | D19: Basis
A20: Starlink | B20: =$B$15*Assumptions!B78 -> 129.276 | C20: =$B$15*Assumptions!B79 -> 186.732 | D20: 18–26x EBITDA (satcom infra comps)
A21: Launch / Space | B21: =$B$16*Assumptions!B80 -> 11.48 | C21: =$B$16*Assumptions!B81 -> 17.22 | D21: 10–15x EBITDA (aerospace/defense comps)
A22: AI / xAI / Grok | B22: =$B$17*Assumptions!B84*Assumptions!B86 -> 10.224 | C22: =$B$17*Assumptions!B84*Assumptions!B87 -> 20.448 | D22: Haircut to OpenAI rev. multiple
A23: Total SOTP Enterprise Value ($B) | B23: =SUM(B20:B22) -> 150.98 | C23: =SUM(C20:C22) -> 224.4
A24: Implied Price per Share | B24: =B23/Assumptions!C7 -> 11.649691 | C24: =C23/Assumptions!C7 -> 17.314815
A25: vs. Current Price | B25: =Assumptions!C6 -> 200
A26: Both bounds imply a steep discount to SpaceX's current ~394x EV/EBITDA trading multiple.

Sheet Merger Model
A1: MERGER MODEL — ACCRETION / DILUTION ANALYSIS
A2: Hypothetical all-stock acquisition of SpaceX by Tesla. Ratio = TSLA shares issued per SPCX share.
A4: Share Issuance Mechanics
A5: Exchange Ratio | B5: New TSLA Shares Issued (B) | C5: Pro Forma Diluted Shares (B) | D5: New Shares as % of PF
A6: 0.3 | B6: =A6*Assumptions!$C$7 -> 3.888 | C6: =Assumptions!$B$7+B6 -> 7.648 | D6: =B6/C6 -> 0.5083682
A7: 0.5 | B7: =A7*Assumptions!$C$7 -> 6.48 | C7: =Assumptions!$B$7+B7 -> 10.24 | D7: =B7/C7 -> 0.6328125
A8: 0.7 | B8: =A8*Assumptions!$C$7 -> 9.072 | C8: =Assumptions!$B$7+B8 -> 12.832 | D8: =B8/C8 -> 0.70698254
A10: Earnings & EBITDA Impact (FY2025A, no synergies)
A11: Ratio | B11: PF Net Income ($B) | C11: PF Diluted Shares (B) | D11: PF EPS | E11: EPS Accretion/(Dilution) | F11: PF EBITDA ($B) | G11: PF EBITDA/Share | H11: EBITDA Accr/(Dil) | I11: Implied SPCX $/sh | J11: Prem/(Disc) to Current
A12: 0.3 | B12: =Assumptions!$B$43+Assumptions!$B$56 -> -1.11 | C12: =C6 -> 7.648 | D12: =B12/C12 -> -0.14513598 | E12: =D12/Assumptions!$B$44-1 -> -1.1343852 | F12: =Assumptions!$B$41+Assumptions!$B$54 -> 21.18 | G12: =F12/C12 -> 2.7693515 | H12: =G12/(Assumptions!$B$41/Assumptions!$B$7)-1 -> -0.28679716 | I12: =A12*Assumptions!$B$6 -> 121.929 | J12: =I12/Assumptions!$C$6-1 -> -0.390355
A13: 0.5 | B13: =Assumptions!$B$43+Assumptions!$B$56 -> -1.11 | C13: =C7 -> 10.24 | D13: =B13/C13 -> -0.10839844 | E13: =D13/Assumptions!$B$44-1 -> -1.1003689 | F13: =Assumptions!$B$41+Assumptions!$B$54 -> 21.18 | G13: =F13/C13 -> 2.0683594 | H13: =G13/(Assumptions!$B$41/Assumptions!$B$7)-1 -> -0.46732663 | I13: =A13*Assumptions!$B$6 -> 203.215 | J13: =I13/Assumptions!$C$6-1 -> 0.016075
A14: 0.7 | B14: =Assumptions!$B$43+Assumptions!$B$56 -> -1.11 | C14: =C8 -> 12.832 | D14: =B14/C14 -> -0.086502494 | E14: =D14/Assumptions!$B$44-1 -> -1.0800949 | F14: =Assumptions!$B$41+Assumptions!$B$54 -> 21.18 | G14: =F14/C14 -> 1.6505611 | H14: =G14/(Assumptions!$B$41/Assumptions!$B$7)-1 -> -0.57492399 | I14: =A14*Assumptions!$B$6 -> 284.501 | J14: =I14/Assumptions!$C$6-1 -> 0.422505
A16: Breakeven Analysis
A17: Combined Adj. EBITDA, no synergies ($B) | B17: =F12 -> 21.18
A18: Tesla Standalone EBITDA/Share | B18: =Assumptions!$B$41/Assumptions!$B$7 -> 3.8829787
A19: Breakeven Exchange Ratio (EBITDA/sh basis) | B19: =(B17/B18-Assumptions!$B$7)/Assumptions!$C$7 -> 0.13075427
A20: Implied SPCX Value at Breakeven ($/sh) | B20: =B19*Assumptions!$B$6 -> 53.142458
A21: Synergies Required to Breakeven — at 0.3x ($B) | B21: =B18*C12-F12 -> 8.5170213
A22: Synergies Required to Breakeven — at 0.5x ($B) | B22: =B18*C13-F12 -> 18.581702
A23: Breakeven = exchange ratio at which pro forma EBITDA/share exactly equals Tesla's standalone EBITDA/share.

Sheet Synergies
A1: SYNERGY ANALYSIS — BEAR / BASE / BULL
A2: Run-rate synergies, $B. Ground-up by line item.
A4: Synergy Line Item | B4: Bear | C4: Base | D4: Bull
A5: Revenue synergies
A6: Starlink × Tesla connectivity bundling | B6: 0 | C6: 0.35 | D6: 1.2
A7: xAI/Grok × FSD data-compute cross-leverage | B7: 0 | C7: 0.5 | D7: 1.8
A8: Tesla Energy × SpaceX/AI data-center & ground infra | B8: 0 | C8: 0.25 | D8: 0.9
A9: Cost synergies
A10: Shared corporate G&A / single public-co. overhead | B10: 0.05 | C10: 0.12 | D10: 0.2
A11: Combined procurement (semis, batteries, avionics) | B11: 0.1 | C11: 0.4 | D11: 0.9
A12: Compute infra. consolidation (Dojo/AI5-6 × Colossus) | B12: 0 | C12: 0.9 | D12: 2.5
A13: Total run-rate synergies ($B) | B13: =SUM(B6:B12) -> 0.15 | C13: =SUM(C6:C12) -> 2.52 | D13: =SUM(D6:D12) -> 7.5
A15: Coverage of Breakeven Thresholds
B16: Synergies Required ($B) | C16: Bull-Case Available ($B) | D16: Bull-Case Coverage %
A17: At 0.3x exchange ratio | B17: ='Merger Model'!B21 -> 8.5170213 | C17: =D13 -> 7.5 | D17: =C17/B17 -> 0.88058956
A18: At 0.5x exchange ratio | B18: ='Merger Model'!B22 -> 18.581702 | C18: =D13 -> 7.5 | D18: =C18/B18 -> 0.40362287
A20: Even the bull-case synergy program falls short of the EBITDA/share breakeven threshold at either ratio.

Sheet Governance
A1: GOVERNANCE — MUSK VOTING CONTROL
A3: Inputs
A4: Musk SPCX Economic Stake % | B4: 0.42
A5: Musk SPCX Shares (B) | B5: =B4*Assumptions!C7 -> 5.4432
A6: Musk TSLA Voting Stake % — Low | B6: 0.18
A7: Musk TSLA Voting Stake % — High | B7: 0.2
A8: Musk TSLA Shares (B) — Low | B8: =B6*Assumptions!B7 -> 0.6768
A9: Musk TSLA Shares (B) — High | B9: =B7*Assumptions!B7 -> 0.752
A10: Musk SPCX Voting Power % (10:1 dual-class) — Low | B10: 0.824
A11: Musk SPCX Voting Power % (10:1 dual-class) — High | B11: 0.851
A13: Pro Forma Voting Stake at Combined, Single-Class Entity
A14: Exchange Ratio | B14: Musk New TSLA Sh. from SPCX Conv. (B) | C14: PF Total Shares (B) | D14: Musk PF Voting Stake — Low | E14: Musk PF Voting Stake — High
A15: 0.3 | B15: =A15*$B$5 -> 1.63296 | C15: ='Merger Model'!C6 -> 7.648 | D15: =($B$8+B15)/C15 -> 0.30200837 | E15: =($B$9+B15)/C15 -> 0.311841
A16: 0.5 | B16: =A16*$B$5 -> 2.7216 | C16: ='Merger Model'!C7 -> 10.24 | D16: =($B$8+B16)/C16 -> 0.331875 | E16: =($B$9+B16)/C16 -> 0.33921875
A17: 0.7 | B17: =A17*$B$5 -> 3.81024 | C17: ='Merger Model'!C8 -> 12.832 | D17: =($B$8+B17)/C17 -> 0.34967581 | E17: =($B$9+B17)/C17 -> 0.35553616
A19: At every ratio, Musk's pro forma voting stake (~30–36%) sits well below his current SpaceX supermajority (82–85%).

Sheet Prob-Weighted Val
A1: PROBABILITY-WEIGHTED VALUATION (SPCX)
A3: Scenario Construction
A4: Scenario | B4: Probability | C4: Implied SPCX Value ($/sh) | D4: Weighted Contribution
A5: No deal (reverts to sell-side consensus) | B5: 0.45 | C5: 164 | D5: =B5*C5 -> 73.8
A6: Deal at fair/no-premium terms (~0.5x) | B6: 0.4 | C6: ='Merger Model'!I13 -> 203.215 | D6: =B6*C6 -> 81.286
A7: Deal at premium terms (~0.7x) | B7: 0.15 | C7: ='Merger Model'!I14 -> 284.501 | D7: =B7*C7 -> 42.67515
A8: Total probability check | B8: =SUM(B5:B7) -> 1
A9: Probability-Weighted SPCX Value | D9: =SUM(D5:D7) -> 197.76115
A10: Current SPCX Price | D10: =Assumptions!C6 -> 200
A11: Premium / (Discount) to Current | D11: =D9/D10-1 -> -0.01119425
A13: Cross-Check: Kalshi-Implied Weights
A14: P(no deal) | B14: 0.47
A15: P(deal) | B15: 0.53
A16: Deal-conditional blend: fair-terms weight | B16: 0.7
A17: Deal-conditional blend: premium-terms weight | B17: 0.3
A18: Deal-Conditional Blended Value ($/sh) | B18: =B16*C6+B17*C7 -> 227.6008
A19: Probability-Weighted Value, Kalshi Weights | B19: =B14*C5+B15*B18 -> 197.70842
A21: Both weighting schemes converge near $197–198, within ~1% of the current $200 price — consistent with market efficiency on the deal-probability dimension.
